Workbook

Sheet Cleaned Data
A2: Dummy Data Cleaned | I2: Business Metrics Calculation
A3: app_name | B3: platform | C3: country | D3: ua_spend_cad | E3: installs | F3: active_users_30d | G3: revenue_30d_cad | H3: revenue_90d_cad | I3: cac_cad | J3: roas_30d | K3: ltv_90d_per_install | L3: retention_30d | M3: ltv_cac_ratio | N3: payback_flag | O3: ltv_gt_cac | P3: eligible_for_ua
A4: Galaxy Gardeners | B4: iOS | C4: Afghanistan | D4: 2700.3 | E4: 9512 | F4: 1882 | G4: 436.82 | H4: 956.11 | I4: =IFERROR(D4/E4,"") -> 0.28388352 | J4: =IFERROR(G4/D4,"") -> 0.16176721 | K4: =IFERROR(H4/E4,"") -> 0.10051619 | L4: =IFERROR(F4/E4,"") -> 0.19785534 | M4: =IFERROR(K4/I4,"") -> 0.35407547 | N4: =IF(J4>1,"Profitable",IF(J4>=0.8,"Breakeven","Needs Optimization")) -> Needs Optimization | O4: =IF(K4>I4,"YES","NO") -> NO | P4: =IF(AND(N4="Profitable",O4="YES"),"YES","NO") -> NO
A5: ABC Adventure | B5: iOS | C5: Albania | D5: 18533.79 | E5: 1541 | F5: 172 | G5: 116.9 | H5: 155.69 | I5: =IFERROR(D5/E5,"") -> 12.027119 | J5: =IFERROR(G5/D5,"") -> 0.0063073985 | K5: =IFERROR(H5/E5,"") -> 0.1010318 | L5: =IFERROR(F5/E5,"") -> 0.11161583 | M5: =IFERROR(K5/I5,"") -> 0.0084003326 | N5: =IF(J5>1,"Profitable",IF(J5>=0.8,"Breakeven","Needs Optimization")) -> Needs Optimization | O5: =IF(K5>I5,"YES","NO") -> NO | P5: =IF(AND(N5="Profitable",O5="YES"),"YES","NO") -> NO
A6: Magic Math Quest | B6: Amazon | C6: Algeria | D6: 20196.76 | E6: 18356 | F6: 4915 | G6: 3789.17 | H6: 8878.63 | I6: =IFERROR(D6/E6,"") -> 1.1002811 | J6: =IFERROR(G6/D6,"") -> 0.18761277 | K6: =IFERROR(H6/E6,"") -> 0.48369089 | L6: =IFERROR(F6/E6,"") -> 0.26775986 | M6: =IFERROR(K6/I6,"") -> 0.43960665 | N6: =IF(J6>1,"Profitable",IF(J6>=0.8,"Breakeven","Needs Optimization")) -> Needs Optimization | O6: =IF(K6>I6,"YES","NO") -> NO | P6: =IF(AND(N6="Profitable",O6="YES"),"YES","NO") -> NO
A7: Pirate Paint Party | B7: iOS | C7: Andorra | D7: 21547.9 | E7: 11649 | F7: 2459 | G7: 2363.94 | H7: 3363.06 | I7: =IFERROR(D7/E7,"") -> 1.8497639 | J7: =IFERROR(G7/D7,"") -> 0.10970628 | K7: =IFERROR(H7/E7,"") -> 0.28869946 | L7: =IFERROR(F7/E7,"") -> 0.21109108 | M7: =IFERROR(K7/I7,"") -> 0.15607368 | N7: =IF(J7>1,"Profitable",IF(J7>=0.8,"Breakeven","Needs Optimization")) -> Needs Optimization | O7: =IF(K7>I7,"YES","NO") -> NO | P7: =IF(AND(N7="Profitable",O7="YES"),"YES","NO") -> NO
A8: Astronaut Academy | B8: iOS | C8: Angola | D8: 12051.42 | E8: 11770 | F8: 4019 | G8: 9700.83 | H8: 18853.31 | I8: =IFERROR(D8/E8,"") -> 1.0239099 | J8: =IFERROR(G8/D8,"") -> 0.80495328 | K8: =IFERROR(H8/E8,"") -> 1.6018105 | L8: =IFERROR(F8/E8,"") -> 0.34146134 | M8: =IFERROR(K8/I8,"") -> 1.5644057 | N8: =IF(J8>1,"Profitable",IF(J8>=0.8,"Breakeven","Needs Optimization")) -> Breakeven | O8: =IF(K8>I8,"YES","NO") -> YES | P8: =IF(AND(N8="Profitable",O8="YES"),"YES","NO") -> NO
A9: Astronaut Academy | B9: iOS | C9: Antigua and Barbuda | D9: 17457.14 | E9: 12350 | F9: 4087 | G9: 2262.81 | H9: 3560.48 | I9: =IFERROR(D9/E9,"") -> 1.4135336 | J9: =IFERROR(G9/D9,"") -> 0.12962089 | K9: =IFERROR(H9/E9,"") -> 0.28829798 | L9: =IFERROR(F9/E9,"") -> 0.33093117 | M9: =IFERROR(K9/I9,"") -> 0.20395552 | N9: =IF(J9>1,"Profitable",IF(J9>=0.8,"Breakeven","Needs Optimization")) -> Needs Optimization | O9: =IF(K9>I9,"YES","NO") -> NO | P9: =IF(AND(N9="Profitable",O9="YES"),"YES","NO") -> NO
A10: Robot Rhyme Run | B10: iOS | C10: Argentina | D10: 25948.9 | E10: 3809 | F10: 960 | G10: 1613.72 | H10: 2412.81 | I10: =IFERROR(D10/E10,"") -> 6.812523 | J10: =IFERROR(G10/D10,"") -> 0.062188378 | K10: =IFERROR(H10/E10,"") -> 0.63344972 | L10: =IFERROR(F10/E10,"") -> 0.25203465 | M10: =IFERROR(K10/I10,"") -> 0.092983132 | N10: =IF(J10>1,"Profitable",IF(J10>=0.8,"Breakeven","Needs Optimization")) -> Needs Optimization | O10: =IF(K10>I10,"YES","NO") -> NO | P10: =IF(AND(N10="Profitable",O10="YES"),"YES","NO") -> NO
A11: Castle Color Camp | B11: iOS | C11: Armenia | D11: 20764.9 | E11: 2839 | F11: 975 | G11: 791.78 | H11: 1184.57 | I11: =IFERROR(D11/E11,"") -> 7.3141599 | J11: =IFERROR(G11/D11,"") -> 0.038130692 | K11: =IFERROR(H11/E11,"") -> 0.41724903 | L11: =IFERROR(F11/E11,"") -> 0.34343079 | M11: =IFERROR(K11/I11,"") -> 0.057046747 | N11: =IF(J11>1,"Profitable",IF(J11>=0.8,"Breakeven","Needs Optimization")) -> Needs Optimization | O11: =IF(K11>I11,"YES","NO") -> NO | P11: =IF(AND(N11="Profitable",O11="YES"),"YES","NO") -> NO
A12: Astronaut Academy | B12: Android | C12: Australia | D12: 29706.65 | E12: 18750 | F12: 3522 | G12: 4389.34 | H12: 6000.78 | I12: =IFERROR(D12/E12,"") -> 1.5843547 | J12: =IFERROR(G12/D12,"") -> 0.14775614 | K12: =IFERROR(H12/E12,"") -> 0.3200416 | L12: =IFERROR(F12/E12,"") -> 0.18784 | M12: =IFERROR(K12/I12,"") -> 0.20200124 | N12: =IF(J12>1,"Profitable",IF(J12>=0.8,"Breakeven","Needs Optimization")) -> Needs Optimization | O12: =IF(K12>I12,"YES","NO") -> NO | P12: =IF(AND(N12="Profitable",O12="YES"),"YES","NO") -> NO
A13: Dino Dash | B13: Android | C13: Austria | D13: 13232.61 | E13: 2668 | F13: 491 | G13: 1568.26 | H13: 2630.93 | I13: =IFERROR(D13/E13,"") -> 4.9597489 | J13: =IFERROR(G13/D13,"") -> 0.11851479 | K13: =IFERROR(H13/E13,"") -> 0.9861057 | L13: =IFERROR(F13/E13,"") -> 0.18403298 | M13: =IFERROR(K13/I13,"") -> 0.1988217 | N13: =IF(J13>1,"Profitable",IF(J13>=0.8,"Breakeven","Needs Optimization")) -> Needs Optimization | O13: =IF(K13>I13,"YES","NO") -> NO | P13: =IF(AND(N13="Profitable",O13="YES"),"YES","NO") -> NO
A14: Galaxy Gardeners | B14: Android | C14: Azerbaijan | D14: 13077.69 | E14: 15535 | F14: 2441 | G14: 1826.96 | H14: 3556.68 | I14: =IFERROR(D14/E14,"") -> 0.84182105 | J14: =IFERROR(G14/D14,"") -> 0.13970051 | K14: =IFERROR(H14/E14,"") -> 0.22894625 | L14: =IFERROR(F14/E14,"") -> 0.15712906 | M14: =IFERROR(K14/I14,"") -> 0.27196546 | N14: =IF(J14>1,"Profitable",IF(J14>=0.8,"Breakeven","Needs Optimization")) -> Needs Optimization | O14: =IF(K14>I14,"YES","NO") -> NO | P14: =IF(AND(N14="Profitable",O14="YES"),"YES","NO") -> NO
A15: Hero Helper HQ | B15: Amazon | C15: Bahamas | D15: 13996.15 | E15: 19621 | F15: 5096 | G15: 6162.23 | H15: 11778.68 | I15: =IFERROR(D15/E15,"") -> 0.71332501 | J15: =IFERROR(G15/D15,"") -> 0.44028036 | K15: =IFERROR(H15/E15,"") -> 0.60030987 | L15: =IFERROR(F15/E15,"") -> 0.25972173 | M15: =IFERROR(K15/I15,"") -> 0.84156572 | N15: =IF(J15>1,"Profitable",IF(J15>=0.8,"Breakeven","Needs Optimization")) -> Needs Optimization | O15: =IF(K15>I15,"YES","NO") -> NO | P15: =IF(AND(N15="Profitable",O15="YES"),"YES","NO") -> NO
... A203: ABC Adventure | B203: Android | C203: Bermuda | D203: 24778.25 | E203: 6237 | F203: 2695 | G203: 7206.98 | H203: 13507.59 | I203: =IFERROR(D203/E203,"") -> 3.9727834 | J203: =IFERROR(G203/D203,"") -> 0.29085912 | K203: =IFERROR(H203/E203,"") -> 2.1657191 | L203: =IFERROR(F203/E203,"") -> 0.43209877 | M203: =IFERROR(K203/I203,"") -> 0.54513898 | N203: =IF(J203>1,"Profitable",IF(J203>=0.8,"Breakeven","Needs Optimization")) -> Needs Optimization | O203: =IF(K203>I203,"YES","NO") -> NO | P203: =IF(AND(N203="Profitable",O203="YES"),"YES","NO") -> NO

Sheet UA Investment Analysis
B1: Executive Summary:
B2: Objective:
B3: Identify which mobile apps should receive additional user acquisition investment.
B4: Method:
B5: Apps were evaluated using CAC, ROAS 30d, LTV 90d, and Retention 30d.
B6: Eligibility Criteria:
B7: ROAS > 1 AND LTV > CAC.
B8: Ranking Method:
B9: Investment Score = ROAS (50%) + LTV (30%) + Retention (20%)
B10: Result:
B11: Top 5 Apps recommended for additional UA investment.
B13: App Eligible for UA Campaing
B14: Eligible for UA Campaing | C14: YES
J15: TOP 5
C16: Values
B17: App Name | C17: UA Spend (Sum) | D17: Installs (Sum) | E17: CAC (Average) | F17: ROAS 30d (Average) | G17: LTV 90d (Average) | H17: Retention 30d (Average) | J17: App | K17: Priority_Score | L17: Priority_Rank
B18: ABC Adventure | C18: 4068.13 | D18: 11823 | E18: 0.3440861 | F18: 2.0465669 | G18: 1.4987922 | H18: 0.49505202 | J18: Ninja Numbers | K18: =IF($J18="","",0.5*IFERROR(INDEX($F$18:$F$30,MATCH($J18,$B$18:$B$30,0)),"")+0.3*IFERROR(INDEX($G$18:$G$30,MATCH($J18,$B$18:$B$30,0)),"")+0.2*IFERROR(INDEX($H$18:$H$30,MATCH($J18,$B$18:$B$30,0)),"")) -> 2.6547813 | L18: =IF($K18="","",RANK($K18,$K$18:$K$30,0)+COUNTIF($K$18:$K18,$K18)-1) -> 1
B19: Dragon Dress-Up | C19: 12888 | D19: 13748 | E19: 0.93744545 | F19: 1.2516124 | G19: 2.9061529 | H19: 0.38965668 | J19: Hero Helper HQ | K19: =IF($J19="","",0.5*IFERROR(INDEX($F$18:$F$30,MATCH($J19,$B$18:$B$30,0)),"")+0.3*IFERROR(INDEX($G$18:$G$30,MATCH($J19,$B$18:$B$30,0)),"")+0.2*IFERROR(INDEX($H$18:$H$30,MATCH($J19,$B$18:$B$30,0)),"")) -> 1.9852439 | L19: =IF($K19="","",RANK($K19,$K$18:$K$30,0)+COUNTIF($K$18:$K19,$K19)-1) -> 2
B20: Farm Friends | C20: 9203.23 | D20: 30260 | E20: 0.31402689 | F20: 2.323302 | G20: 1.3939633 | H20: 0.32861318 | J20: Galaxy Gardeners | K20: =IF($J20="","",0.5*IFERROR(INDEX($F$18:$F$30,MATCH($J20,$B$18:$B$30,0)),"")+0.3*IFERROR(INDEX($G$18:$G$30,MATCH($J20,$B$18:$B$30,0)),"")+0.2*IFERROR(INDEX($H$18:$H$30,MATCH($J20,$B$18:$B$30,0)),"")) -> 1.7881914 | L20: =IF($K20="","",RANK($K20,$K$18:$K$30,0)+COUNTIF($K$18:$K20,$K20)-1) -> 3
B21: Galaxy Gardeners | C21: 7252.74 | D21: 26834 | E21: 0.36781777 | F21: 2.8827474 | G21: 0.98662688 | H21: 0.2541483 | J21: Super Chef Jr | K21: =IF($J21="","",0.5*IFERROR(INDEX($F$18:$F$30,MATCH($J21,$B$18:$B$30,0)),"")+0.3*IFERROR(INDEX($G$18:$G$30,MATCH($J21,$B$18:$B$30,0)),"")+0.2*IFERROR(INDEX($H$18:$H$30,MATCH($J21,$B$18:$B$30,0)),"")) -> 1.6920298 | L21: =IF($K21="","",RANK($K21,$K$18:$K$30,0)+COUNTIF($K$18:$K21,$K21)-1) -> 4
B22: Hero Helper HQ | C22: 3600.63 | D22: 19642 | E22: 0.1833128 | F22: 3.3500526 | G22: 0.84025608 | H22: 0.29070359 | J22: Farm Friends | K22: =IF($J22="","",0.5*IFERROR(INDEX($F$18:$F$30,MATCH($J22,$B$18:$B$30,0)),"")+0.3*IFERROR(INDEX($G$18:$G$30,MATCH($J22,$B$18:$B$30,0)),"")+0.2*IFERROR(INDEX($H$18:$H$30,MATCH($J22,$B$18:$B$30,0)),"")) -> 1.6455626 | L22: =IF($K22="","",RANK($K22,$K$18:$K$30,0)+COUNTIF($K$18:$K22,$K22)-1) -> 5
B23: Jungle Jumpers | C23: 2260.83 | D23: 18948 | E23: 0.11931761 | F23: 1.0422677 | G23: 0.20124604 | H23: 0.49841672
B24: Magic Math Quest | C24: 5347.53 | D24: 18059 | E24: 0.2961144 | F24: 1.4266886 | G24: 0.92364195 | H24: 0.48031452 | J24: Metric | K24: Weight %
B25: Ninja Numbers | C25: 8542.73 | D25: 18633 | E25: 0.4899074 | F25: 3.5849845 | G25: 2.5663213 | H25: 0.46196308 | J25: ROAS | K25: 0.5
B26: Ocean Odyssey Kids | C26: 4211.11 | D26: 13035 | E26: 0.32306176 | F26: 1.2764568 | G26: 0.60690832 | H26: 0.34783276 | J26: LTV | K26: 0.3
B27: Puzzle Planet | C27: 26840.88 | D27: 32252 | E27: 0.80922517 | F27: 1.7012224 | G27: 2.272813 | H27: 0.38836133 | J27: Retention | K27: 0.2
B28: Rainbow Rescue | C28: 6656.71 | D28: 16413 | E28: 0.40557546 | F28: 2.1893818 | G28: 1.329777 | H28: 0.29251203
B29: Robot Rhyme Run | C29: 3621.9 | D29: 19091 | E29: 0.18971767 | F29: 1.1139043 | G29: 0.29227751 | H29: 0.47875962
B30: Super Chef Jr | C30: 7081.7 | D30: 19680 | E30: 0.35984248 | F30: 2.3347162 | G30: 1.5660127 | H30: 0.27433943
B32: Top 5 App Metrics per Platform
B33: Eligible for UA Campaing | C33: YES
B35: App Name | C35: ROAS 30d (Average) | D35: CAC (Average) | E35: LTV 90d (Average)
B36: Farm Friends | C36: 2.323302 | D36: 0.31402689 | E36: 1.3939633
B37: iOS | C37: 2.323302 | D37: 0.31402689 | E37: 1.3939633
B38: Galaxy Gardeners | C38: 2.8827474 | D38: 0.36781777 | E38: 0.98662688
B39: Amazon | C39: 4.6493454 | D39: 0.11883736 | E39: 0.80730841
B40: Android | C40: 1.1161494 | D40: 0.61679819 | E40: 1.1659453
B41: Hero Helper HQ | C41: 3.3500526 | D41: 0.1833128 | E41: 0.84025608
B42: Android | C42: 3.3500526 | D42: 0.1833128 | E42: 0.84025608
B43: Ninja Numbers | C43: 3.5849845 | D43: 0.4899074 | E43: 2.5663213
...

Sheet Simplified Performance Table
A2: App | B2: Avg ROAS 30d | C2: Simulated ROAS 90d | D2: Simulated CAC Trend % | E2: Avg Retention 30d | F2: Sim Retention 90d | G2: Avg LTV 90d per install | H2: Keep Investing?
A3: Farm Friends | B3: =IFERROR(INDEX('UA Investment Analysis'!$F:$F, MATCH($A3, 'UA Investment Analysis'!$B:$B, 0)), "") -> 2.323302 | C3: =IF($B3="","",$B3*1.15) -> 2.6717973 | D3: 0.03 | E3: =IFERROR(INDEX('UA Investment Analysis'!$H:$H, MATCH($A3, 'UA Investment Analysis'!$B:$B, 0)), "") -> 0.32861318 | F3: =IF($E3="","",$E3*0.65) -> 0.21359857 | G3: =IFERROR(INDEX('UA Investment Analysis'!$G:$G, MATCH($A3, 'UA Investment Analysis'!$B:$B, 0)), "") -> 1.3939633 | H3: =IF(AND(C3>1.05,D3<=0.05,G3>0),"KEEP INVESTING","REVIEW / OPTIMIZE") -> KEEP INVESTING
A4: Galaxy Gardeners | B4: =IFERROR(INDEX('UA Investment Analysis'!$F:$F, MATCH($A4, 'UA Investment Analysis'!$B:$B, 0)), "") -> 2.8827474 | C4: =IF($B4="","",$B4*1.15) -> 3.3151595 | D4: 0.03 | E4: =IFERROR(INDEX('UA Investment Analysis'!$H:$H, MATCH($A4, 'UA Investment Analysis'!$B:$B, 0)), "") -> 0.2541483 | F4: =IF($E4="","",$E4*0.65) -> 0.16519639 | G4: =IFERROR(INDEX('UA Investment Analysis'!$G:$G, MATCH($A4, 'UA Investment Analysis'!$B:$B, 0)), "") -> 0.98662688 | H4: =IF(AND(C4>1.05,D4<=0.05,G4>0),"KEEP INVESTING","REVIEW / OPTIMIZE") -> KEEP INVESTING
A5: Hero Helper HQ | B5: =IFERROR(INDEX('UA Investment Analysis'!$F:$F, MATCH($A5, 'UA Investment Analysis'!$B:$B, 0)), "") -> 3.3500526 | C5: =IF($B5="","",$B5*1.15) -> 3.8525605 | D5: 0.03 | E5: =IFERROR(INDEX('UA Investment Analysis'!$H:$H, MATCH($A5, 'UA Investment Analysis'!$B:$B, 0)), "") -> 0.29070359 | F5: =IF($E5="","",$E5*0.65) -> 0.18895734 | G5: =IFERROR(INDEX('UA Investment Analysis'!$G:$G, MATCH($A5, 'UA Investment Analysis'!$B:$B, 0)), "") -> 0.84025608 | H5: =IF(AND(C5>1.05,D5<=0.05,G5>0),"KEEP INVESTING","REVIEW / OPTIMIZE") -> KEEP INVESTING
A6: Ninja Numbers | B6: =IFERROR(INDEX('UA Investment Analysis'!$F:$F, MATCH($A6, 'UA Investment Analysis'!$B:$B, 0)), "") -> 3.5849845 | C6: =IF($B6="","",$B6*1.15) -> 4.1227322 | D6: 0.03 | E6: =IFERROR(INDEX('UA Investment Analysis'!$H:$H, MATCH($A6, 'UA Investment Analysis'!$B:$B, 0)), "") -> 0.46196308 | F6: =IF($E6="","",$E6*0.65) -> 0.300276 | G6: =IFERROR(INDEX('UA Investment Analysis'!$G:$G, MATCH($A6, 'UA Investment Analysis'!$B:$B, 0)), "") -> 2.5663213 | H6: =IF(AND(C6>1.05,D6<=0.05,G6>0),"KEEP INVESTING","REVIEW / OPTIMIZE") -> KEEP INVESTING
A7: Super Chef Jr | B7: =IFERROR(INDEX('UA Investment Analysis'!$F:$F, MATCH($A7, 'UA Investment Analysis'!$B:$B, 0)), "") -> 2.3347162 | C7: =IF($B7="","",$B7*0.95) -> 2.2179804 | D7: 0.08 | E7: =IFERROR(INDEX('UA Investment Analysis'!$H:$H, MATCH($A7, 'UA Investment Analysis'!$B:$B, 0)), "") -> 0.27433943 | F7: =IF($E7="","",$E7*0.65) -> 0.17832063 | G7: =IFERROR(INDEX('UA Investment Analysis'!$G:$G, MATCH($A7, 'UA Investment Analysis'!$B:$B, 0)), "") -> 1.5660127 | H7: =IF(AND(C7>1.05,D7<=0.05,G7>0),"KEEP INVESTING","REVIEW / OPTIMIZE") -> REVIEW / OPTIMIZE

Sheet Data
B2: App Name | C2: UA Spend (Sum) | D2: Installs (Sum) | E2: CAC (Average) | F2: ROAS 30d (Average) | G2: LTV 90d (Average) | H2: Retention 30d (Average)
B3: ABC Adventure | C3: 4068.13 | D3: 11823 | E3: 0.3440861 | F3: 2.0465669 | G3: 1.4987922 | H3: 0.49505202
B4: Dragon Dress-Up | C4: 12888 | D4: 13748 | E4: 0.93744545 | F4: 1.2516124 | G4: 2.9061529 | H4: 0.38965668
B5: Farm Friends | C5: 9203.23 | D5: 30260 | E5: 0.31402689 | F5: 2.323302 | G5: 1.3939633 | H5: 0.32861318
B6: Galaxy Gardeners | C6: 7252.74 | D6: 26834 | E6: 0.36781777 | F6: 2.8827474 | G6: 0.98662688 | H6: 0.2541483
B7: Hero Helper HQ | C7: 3600.63 | D7: 19642 | E7: 0.1833128 | F7: 3.3500526 | G7: 0.84025608 | H7: 0.29070359
B8: Jungle Jumpers | C8: 2260.83 | D8: 18948 | E8: 0.11931761 | F8: 1.0422677 | G8: 0.20124604 | H8: 0.49841672
B9: Magic Math Quest | C9: 5347.53 | D9: 18059 | E9: 0.2961144 | F9: 1.4266886 | G9: 0.92364195 | H9: 0.48031452
B10: Ninja Numbers | C10: 8542.73 | D10: 18633 | E10: 0.4899074 | F10: 3.5849845 | G10: 2.5663213 | H10: 0.46196308
B11: Ocean Odyssey Kids | C11: 4211.11 | D11: 13035 | E11: 0.32306176 | F11: 1.2764568 | G11: 0.60690832 | H11: 0.34783276
B12: Puzzle Planet | C12: 26840.88 | D12: 32252 | E12: 0.80922517 | F12: 1.7012224 | G12: 2.272813 | H12: 0.38836133
B13: Rainbow Rescue | C13: 6656.71 | D13: 16413 | E13: 0.40557546 | F13: 2.1893818 | G13: 1.329777 | H13: 0.29251203
B14: Robot Rhyme Run | C14: 3621.9 | D14: 19091 | E14: 0.18971767 | F14: 1.1139043 | G14: 0.29227751 | H14: 0.47875962
B15: Super Chef Jr | C15: 7081.7 | D15: 19680 | E15: 0.35984248 | F15: 2.3347162 | G15: 1.5660127 | H15: 0.27433943
B17: App Name | C17: CAC (Average) | D17: ROAS 30d (Average)
B18: Ninja Numbers | C18: 0.4899074 | D18: 3.5849845
B19: Hero Helper HQ | C19: 0.1833128 | D19: 3.3500526
B20: Galaxy Gardeners | C20: 0.36781777 | D20: 2.8827474
B21: Super Chef Jr | C21: 0.35984248 | D21: 2.3347162
B22: Farm Friends | C22: 0.31402689 | D22: 2.323302
B24: App Name | C24: CAC (Average) | D24: LTV 90d (Average)
B25: Ninja Numbers | C25: 0.4899074 | D25: 2.5663213
B26: Super Chef Jr | C26: 0.35984248 | D26: 1.5660127
B27: Farm Friends | C27: 0.31402689 | D27: 1.3939633
B28: Galaxy Gardeners | C28: 0.36781777 | D28: 0.98662688
B29: Hero Helper HQ | C29: 0.1833128 | D29: 0.84025608
B31: App | C31: Day | D31: Retention
B32: Farm Friends | C32: 30 | D32: ='Simplified Performance Table'!E3 -> 0.32861318
B33: Farm Friends | C33: 90 | D33: ='Simplified Performance Table'!F3 -> 0.21359857
B34: Galaxy Gardeners | C34: 30 | D34: ='Simplified Performance Table'!E4 -> 0.2541483
B35: Galaxy Gardeners | C35: 90 | D35: ='Simplified Performance Table'!F4 -> 0.16519639
B36: Hero Helper HQ | C36: 30 | D36: ='Simplified Performance Table'!E5 -> 0.29070359
B37: Hero Helper HQ | C37: 90 | D37: ='Simplified Performance Table'!F5 -> 0.18895734
B38: Ninja Numbers | C38: 30 | D38: ='Simplified Performance Table'!E6 -> 0.46196308
B39: Ninja Numbers | C39: 90 | D39: ='Simplified Performance Table'!F6 -> 0.300276
B40: Super Chef Jr | C40: 30 | D40: ='Simplified Performance Table'!E7 -> 0.27433943
B41: Super Chef Jr | C41: 90 | D41: ='Simplified Performance Table'!F7 -> 0.17832063
